2021-03-04 19:16:31,245:DEBUG:certbot._internal.main:certbot version: 1.10.1
2021-03-04 19:16:31,246:DEBUG:certbot._internal.main:Arguments: ['--standalone']
2021-03-04 19:16:31,246:DEBUG:certbot._internal.main:Discovered plugins: PluginsRegistry(PluginEntryPoint#manual,PluginEntryPoint#null,PluginEntryPoint#standalone,PluginEntryPoint#webroot)
2021-03-04 19:16:31,261:DEBUG:certbot._internal.log:Root logging level set at 20
2021-03-04 19:16:31,262:INFO:certbot._internal.log:Saving debug log to /var/log/letsencrypt/letsencrypt.log
2021-03-04 19:16:31,263:DEBUG:certbot._internal.plugins.selection:Requested authenticator standalone and installer None
2021-03-04 19:16:31,267:DEBUG:certbot._internal.plugins.selection:Single candidate plugin: * standalone
Description: Spin up a temporary webserver
Interfaces: IAuthenticator, IPlugin
Entry point: standalone = certbot._internal.plugins.standalone:Authenticator
Initialized: <certbot._internal.plugins.standalone.Authenticator object at 0x803534690>
Prep: True
2021-03-04 19:16:31,267:DEBUG:certbot._internal.plugins.selection:Selected authenticator <certbot._internal.plugins.standalone.Authenticator object at 0x803534690> and installer None
2021-03-04 19:16:31,267:INFO:certbot._internal.plugins.selection:Plugins selected: Authenticator standalone, Installer None
2021-03-04 19:16:31,273:DEBUG:certbot._internal.main:Picked account: <Account(RegistrationResource(body=Registration(key=None, contact=(), agreement=None, status=None, terms_of_service_agreed=None, only_return_existing=None, external_account_binding=None), uri='https://acme-v02.api.letsencrypt.org/acme/acct/114650385', new_authzr_uri=None, terms_of_service=None), 03fe6329a45bf8db73ead07639756b7e, Meta(creation_dt=datetime.datetime(2021, 3, 4, 18, 5, 8, tzinfo=<UTC>), creation_host='paquet', register_to_eff=None))>
2021-03-04 19:16:31,273:DEBUG:acme.client:Sending GET request to https://acme-v02.api.letsencrypt.org/directory.
2021-03-04 19:16:31,277:DEBUG:urllib3.connectionpool:Starting new HTTPS connection (1): acme-v02.api.letsencrypt.org:443
2021-03-04 19:16:31,844:DEBUG:urllib3.connectionpool:https://acme-v02.api.letsencrypt.org:443 "GET /directory HTTP/1.1" 200 658
2021-03-04 19:16:31,845:DEBUG:acme.client:Received response:
HTTP 200
Server: nginx
Date: Thu, 04 Mar 2021 19:16:32 GMT
Content-Type: application/json
Content-Length: 658
Connection: keep-alive
Cache-Control: public, max-age=0, no-cache
X-Frame-Options: DENY
Strict-Transport-Security: max-age=604800

{
  "EeT6zGU8ORg": "https://community.letsencrypt.org/t/adding-random-entries-to-the-directory/33417",
  "keyChange": "https://acme-v02.api.letsencrypt.org/acme/key-change",
  "meta": {
    "caaIdentities": [
      "letsencrypt.org"
    ],
    "termsOfService": "https://letsencrypt.org/documents/LE-SA-v1.2-November-15-2017.pdf",
    "website": "https://letsencrypt.org"
  },
  "newAccount": "https://acme-v02.api.letsencrypt.org/acme/new-acct",
  "newNonce": "https://acme-v02.api.letsencrypt.org/acme/new-nonce",
  "newOrder": "https://acme-v02.api.letsencrypt.org/acme/new-order",
  "revokeCert": "https://acme-v02.api.letsencrypt.org/acme/revoke-cert"
}
2021-03-04 19:16:31,846:DEBUG:certbot.display.ops:No installer, picking names manually
2021-03-04 19:16:42,828:DEBUG:certbot._internal.plugins.selection:Requested authenticator standalone and installer <certbot._internal.cli.cli_utils._Default object at 0x8035eea50>
2021-03-04 19:16:42,836:DEBUG:urllib3.connectionpool:Starting new HTTP connection (1): r3.o.lencr.org:80
2021-03-04 19:16:42,973:DEBUG:urllib3.connectionpool:http://r3.o.lencr.org:80 "POST / HTTP/1.1" 200 503
2021-03-04 19:16:42,974:DEBUG:certbot.ocsp:OCSP response for certificate /usr/local/etc/letsencrypt/archive/gdpr-presentation.tech/cert1.pem is signed by the certificate's issuer.
2021-03-04 19:16:42,977:DEBUG:certbot.ocsp:OCSP certificate status for /usr/local/etc/letsencrypt/archive/gdpr-presentation.tech/cert1.pem is: OCSPCertStatus.GOOD
2021-03-04 19:16:42,983:INFO:certbot._internal.renewal:Cert not yet due for renewal
2021-03-04 19:16:56,525:DEBUG:certbot._internal.log:Exiting abnormally:
Traceback (most recent call last):
  File "/usr/local/bin/certbot", line 11, in <module>
    load_entry_point('certbot==1.10.1', 'console_scripts', 'certbot')()
  File "/usr/local/lib/python3.7/site-packages/certbot/main.py", line 15, in main
    return internal_main.main(cli_args)
  File "/usr/local/lib/python3.7/site-packages/certbot/_internal/main.py", line 1412, in main
    return config.func(config, plugins)
  File "/usr/local/lib/python3.7/site-packages/certbot/_internal/main.py", line 1286, in certonly
    should_get_cert, lineage = _find_cert(config, domains, certname)
  File "/usr/local/lib/python3.7/site-packages/certbot/_internal/main.py", line 331, in _find_cert
    action, lineage = _find_lineage_for_domains_and_certname(config, domains, certname)
  File "/usr/local/lib/python3.7/site-packages/certbot/_internal/main.py", line 363, in _find_lineage_for_domains_and_certname
    return _find_lineage_for_domains(config, domains)
  File "/usr/local/lib/python3.7/site-packages/certbot/_internal/main.py", line 307, in _find_lineage_for_domains
    return _handle_identical_cert_request(config, ident_names_cert)
  File "/usr/local/lib/python3.7/site-packages/certbot/_internal/main.py", line 265, in _handle_identical_cert_request
    "Operation canceled. You may re-run the client.")
certbot.errors.Error: Operation canceled. You may re-run the client.
2021-03-04 19:16:56,527:ERROR:certbot._internal.log:Operation canceled. You may re-run the client.
